Workbook
Name Slicer_Category: #N/A
Name Slicer_City: #N/A
Name Slicer_Month: #N/A
Name Slicer_Product_name: #N/A

Sheet Customer_Master
A1: Customer ID | B1: Customer Name | C1: City
A2: C0001 | B2: Riya Sharma | C2: Delhi
A3: C0002 | B3: Arjun Mehta | C3: Mumbai
A4: C0003 | B4: Meena Joshi | C4: Mumbai
A5: C0004 | B5: Mohan Das | C5: Mumbai
A6: C0005 | B6: Riya Sharma | C6: Jaipur
A7: C0006 | B7: Amit Kumar | C7: Pune
A8: C0007 | B8: Neha Singh | C8: Lucknow
A9: C0008 | B9: Anjali Gupta | C9: Lucknow
A10: C0009 | B10: Vikas Yadav | C10: Mumbai
A11: C0010 | B11: Meena Joshi | C11: Mumbai
A12: C0011 | B12: Amit Kumar | C12: Ahmedabad
... A15: C0014 | B15: Riya Sharma | C15: Jaipur
A16: C0015 | B16: Riya Sharma
A17: C0016 | B17: Rahul Sharma | C17: Jaipur
A18: C0017 | B18: Amit Kumar | C18: Delhi
A19: C0018 | B19: Sneha Roy | C19: Mumbai
A20: C0019 | B20: Meena Joshi | C20: Noida
A21: C0020 | B21: Riya Sharma | C21: Lucknow
A22: C0021 | B22: Sneha Roy | C22: Chandigarh
A23: C0022 | B23: Meena Joshi | C23: Ahmedabad
A24: C0023 | B24: Vikas Yadav | C24: Chandigarh
A25: C0024 | B25: Karan Patel | C25: Ahmedabad
A26: C0025 | B26: Priya Verma | C26: Delhi
A27: C0026 | B27: Meena Joshi | C27: Mumbai
A28: C0027 | B28: Neha Singh | C28: Chandigarh
... A67: C0066 | B67: Karan Patel | C67: Jaipur
A68: C0067 | B68: Neha Singh
A69: C0068 | B69: Arjun Mehta | C69: Jaipur
A70: C0069 | B70: Mohan Das | C70: Ahmedabad
A71: C0070 | B71: Vikas Yadav | C71: Pune
A72: C0071 | B72: Karan Patel | C72: Jaipur
A73: C0072 | B73: Arjun Mehta | C73: Pune
A74: C0073 | B74: Vikas Yadav | C74: Delhi
A75: C0074 | B75: Riya Sharma | C75: Chandigarh
A76: C0075 | B76: Mohan Das | C76: Jaipur
A77: C0076 | B77: Rahul Sharma | C77: Jaipur
A78: C0077 | B78: Karan Patel | C78: Noida
A79: C0078 | B79: Priya Verma | C79: Jaipur
A80: C0079 | B80: Amit Kumar | C80: Mumbai
...

Sheet Product_Master
A1: Product ID | B1: Product Name | C1: Category | D1: Cost Price | E1: Selling Price
A2: P001 | B2: Mobile | C2: Electronics | D2: 20000 | E2: 25000
A3: P002 | B3: Mouse | C3: Accessories | D3: 500 | E3: 800
A4: P003 | B4: Keyboard | C4: Accessories | D4: 900 | E4: 1500
A5: P004 | B5: Tablet | C5: Electronics | D5: 15000 | E5: 18000
A6: P005 | B6: Mouse | C6: Accessories | D6: 500 | E6: 800
A7: P006 | B7: Laptop | C7: Electronics | D7: 42000 | E7: 50000
A8: P007 | B8: Mobile | C8: Electronics | D8: 20000 | E8: 25000
A9: P008 | B9: Tablet | C9: Electronics | D9: 15000 | E9: 18000
A10: P009 | B10: Speaker | C10: Accessories | D10: 2000 | E10: 3000
A11: P010 | B11: Monitor | C11: Accessories | D11: 9000 | E11: 12000
A12: P011 | B12: Keyboard | C12: Accessories | D12: 900 | E12: 1500
A13: P012 | B13: Keyboard | C13: Accessories | D13: 900 | E13: 1500
... A101: P100 | B101: Speaker | C101: Accessories | D101: 2000 | E101: 3000

Sheet Sales_Data
A1: Order ID | B1: Order Date | C1: Customer ID | D1: Product ID | E1: Quantity
A2: O00001 | B2: 45748 | C2: C0020 | D2: P090 | E2: 2
A3: O00002 | B3: 46015 | C3: C0142 | D3: P035 | E3: 4
A4: O00003 | B4: 45668 | C4: C0300 | D4: P072 | E4: 2
A5: O00004 | B5: 45846 | C5: C0069 | D5: P018 | E5: 5
A6: O00005 | B6: 45960 | C6: C0130 | D6: P058 | E6: 2
A7: O00006 | B7: 45796 | C7: C0282 | D7: P042 | E7: 1
A8: O00007 | B8: 45913 | C8: C0031 | D8: P016 | E8: 3
A9: O00008 | B9: 45895 | C9: C0157 | D9: P024 | E9: 1
A10: O00009 | B10: 45866 | C10: C0114 | D10: P027 | E10: 4
A11: O00010 | B11: 45853 | C11: C0218 | D11: P035 | E11: 5
A12: O00011 | B12: 45758 | C12: C0063 | D12: P032 | E12: 4
A13: O00012 | B13: 45667 | C13: C9999 | D13: P075 | E13: 1
... A1001: O01000 | B1001: 45860 | C1001: C0231 | D1001: P040 | E1001: 2

Sheet Pivot Table 1
A3: Row Labels | B3: Sum of Selling Price
A4: Laptop | B4: 7500000
A5: Mobile | B5: 3850000
A6: Monitor | B6: 1536000
A7: Printer | B7: 1245000
A8: Tablet | B8: 1116000
A9: Speaker | B9: 360000
A10: Keyboard | B10: 232500
A11: Mouse | B11: 118400
A12: Grand Total | B12: 15957900

Sheet Pivot Table 2
A3: Row Labels | B3: Sum of Profit
A4: Mouse | B4: 132300
A5: Keyboard | B5: 287400
A6: Speaker | B6: 375000
A7: Tablet | B7: 519000
A8: Printer | B8: 720000
A9: Monitor | B9: 1257000
A10: Mobile | B10: 2275000
A11: Laptop | B11: 3592000
A12: Grand Total | B12: 9157700

Sheet Pivot Table 3
A3: Row Labels | B3: Sum of Gross Sales
A4: Jaipur | B4: 7768800
A5: Lucknow | B5: 7753800
A6: Ahmedabad | B6: 6942400
A7: Mumbai | B7: 4979100
A8: Chandigarh | B8: 4261800
B9: 4249600
A10: Pune | B10: 4063500
A11: Delhi | B11: 3956300
A12: Noida | B12: 3788000
A13: Grand Total | B13: 47763300

Sheet Pivot Table 4
A3: Row Labels | B3: Sum of Gross Sales
A4: Jan | B4: 4719300
A5: Feb | B5: 3330300
A6: Mar | B6: 3274600
A7: Apr | B7: 3407900
A8: May | B8: 5037200
A9: Jun | B9: 3957500
A10: Jul | B10: 3903600
A11: Aug | B11: 4015100
A12: Sep | B12: 2832900
A13: Oct | B13: 3970900
A14: Nov | B14: 4349900
A15: Dec | B15: 4964100
A16: Grand Total | B16: 47763300

Sheet Pivot Table 5
A3: Row Labels | B3: Sum of Profit
A4: Jan | B4: 881200
A5: Feb | B5: 630900
A6: Mar | B6: 629800
A7: Apr | B7: 670100
A8: May | B8: 943200
A9: Jun | B9: 760300
A10: Jul | B10: 764300
A11: Aug | B11: 741800
A12: Sep | B12: 558800
A13: Oct | B13: 775800
A14: Nov | B14: 844200
A15: Dec | B15: 957300
A16: Grand Total | B16: 9157700

Sheet Pivot Table 6
A3: Row Labels | B3: Sum of Gross Sales
A4: Riya Sharma | B4: 6244000
A5: Sneha Roy | B5: 4644400
A6: Karan Patel | B6: 4528300
A7: Arjun Mehta | B7: 4357500
A8: Rahul Sharma | B8: 4081800
A9: Amit Kumar | B9: 3788100
A10: Vikas Yadav | B10: 3649800
A11: Meena Joshi | B11: 3644900
A12: Anjali Gupta | B12: 3339200
A13: Neha Singh | B13: 2756400
A14: Grand Total | B14: 41034400

Sheet Sheet7
A3: Row Labels | B3: Sum of Profit
A4: Accessories | B4: 2051700
A5: Electronics | B5: 7106000
A6: Grand Total | B6: 9157700

Sheet Clean_Data
A1: Order ID | B1: Order Date | C1: Month | D1: Customer ID | E1: Product ID | F1: Quantity | G1: Customer name | H1: City | I1: Product name | J1: Category | K1: Cost Price | L1: Selling Price | M1: Gross Sales | N1: Total Cost | O1: Profit | P1: Profit % | Q1: Profit Category
A2: O00001 | B2: 45748 | C2: =TEXT(B2,"MMMM") -> April | D2: C0020 | E2: P090 | F2: 2 | G2: Riya Sharma | H2: Lucknow | I2: Printer | J2: =_xlfn.XLOOKUP(E2, Product_Master!$A$2:$A$101, Product_Master!$C$2:$C$101) -> Electronics | K2: =_xlfn.XLOOKUP(E2, Product_Master!$A$2:$A$101, Product_Master!$D$2:$D$101) -> 12000 | L2: =_xlfn.XLOOKUP(E2, Product_Master!$A$2:$A$101, Product_Master!$E$2:$E$101) -> 15000 | M2: =F2*L2 -> 30000 | N2: =F2*K2 -> 24000 | O2: =M2-N2 -> 6000 | P2: =O2/M2 -> 0.2 | Q2: {=_xlfn.IFS(P2:P1001>=25%, "High Profit", P2:P1001>=10%, "Low Profit")} -> Low Profit
A3: O00002 | B3: 46015 | C3: =TEXT(B3,"MMMM") -> December | D3: C0142 | E3: P035 | F3: 4 | G3: Karan Patel | H3: Jaipur | I3: Monitor | J3: =_xlfn.XLOOKUP(E3, Product_Master!$A$2:$A$101, Product_Master!$C$2:$C$101) -> Accessories | K3: =_xlfn.XLOOKUP(E3, Product_Master!$A$2:$A$101, Product_Master!$D$2:$D$101) -> 9000 | L3: =_xlfn.XLOOKUP(E3, Product_Master!$A$2:$A$101, Product_Master!$E$2:$E$101) -> 12000 | M3: =F3*L3 -> 48000 | N3: =F3*K3 -> 36000 | O3: =M3-N3 -> 12000 | P3: =O3/M3 -> 0.25 | Q3: High Profit
A4: O00003 | B4: 45668 | C4: =TEXT(B4,"MMMM") -> January | D4: C0300 | E4: P072 | F4: 2 | G4: Rahul Sharma | H4: Pune | I4: Mobile | J4: =_xlfn.XLOOKUP(E4, Product_Master!$A$2:$A$101, Product_Master!$C$2:$C$101) -> Electronics | K4: =_xlfn.XLOOKUP(E4, Product_Master!$A$2:$A$101, Product_Master!$D$2:$D$101) -> 20000 | L4: =_xlfn.XLOOKUP(E4, Product_Master!$A$2:$A$101, Product_Master!$E$2:$E$101) -> 25000 | M4: =F4*L4 -> 50000 | N4: =F4*K4 -> 40000 | O4: =M4-N4 -> 10000 | P4: =O4/M4 -> 0.2 | Q4: Low Profit
A5: O00004 | B5: 45846 | C5: =TEXT(B5,"MMMM") -> July | D5: C0069 | E5: P018 | F5: 5 | G5: Mohan Das | H5: Ahmedabad | I5: Laptop | J5: =_xlfn.XLOOKUP(E5, Product_Master!$A$2:$A$101, Product_Master!$C$2:$C$101) -> Electronics | K5: =_xlfn.XLOOKUP(E5, Product_Master!$A$2:$A$101, Product_Master!$D$2:$D$101) -> 42000 | L5: =_xlfn.XLOOKUP(E5, Product_Master!$A$2:$A$101, Product_Master!$E$2:$E$101) -> 50000 | M5: =F5*L5 -> 250000 | N5: =F5*K5 -> 210000 | O5: =M5-N5 -> 40000 | P5: =O5/M5 -> 0.16 | Q5: Low Profit
A6: O00005 | B6: 45960 | C6: =TEXT(B6,"MMMM") -> October | D6: C0130 | E6: P058 | F6: 2 | G6: Rahul Sharma | H6: Delhi | I6: Keyboard | J6: =_xlfn.XLOOKUP(E6, Product_Master!$A$2:$A$101, Product_Master!$C$2:$C$101) -> Accessories | K6: =_xlfn.XLOOKUP(E6, Product_Master!$A$2:$A$101, Product_Master!$D$2:$D$101) -> 900 | L6: =_xlfn.XLOOKUP(E6, Product_Master!$A$2:$A$101, Product_Master!$E$2:$E$101) -> 1500 | M6: =F6*L6 -> 3000 | N6: =F6*K6 -> 1800 | O6: =M6-N6 -> 1200 | P6: =O6/M6 -> 0.4 | Q6: High Profit
A7: O00006 | B7: 45796 | C7: =TEXT(B7,"MMMM") -> May | D7: C0282 | E7: P042 | F7: 1 | G7: Karan Patel | H7: Mumbai | I7: Keyboard | J7: =_xlfn.XLOOKUP(E7, Product_Master!$A$2:$A$101, Product_Master!$C$2:$C$101) -> Accessories | K7: =_xlfn.XLOOKUP(E7, Product_Master!$A$2:$A$101, Product_Master!$D$2:$D$101) -> 900 | L7: =_xlfn.XLOOKUP(E7, Product_Master!$A$2:$A$101, Product_Master!$E$2:$E$101) -> 1500 | M7: =F7*L7 -> 1500 | N7: =F7*K7 -> 900 | O7: =M7-N7 -> 600 | P7: =O7/M7 -> 0.4 | Q7: High Profit
A8: O00007 | B8: 45913 | C8: =TEXT(B8,"MMMM") -> September | D8: C0031 | E8: P016 | F8: 3 | G8: Arjun Mehta | H8: Chandigarh | I8: Mobile | J8: =_xlfn.XLOOKUP(E8, Product_Master!$A$2:$A$101, Product_Master!$C$2:$C$101) -> Electronics | K8: =_xlfn.XLOOKUP(E8, Product_Master!$A$2:$A$101, Product_Master!$D$2:$D$101) -> 20000 | L8: =_xlfn.XLOOKUP(E8, Product_Master!$A$2:$A$101, Product_Master!$E$2:$E$101) -> 25000 | M8: =F8*L8 -> 75000 | N8: =F8*K8 -> 60000 | O8: =M8-N8 -> 15000 | P8: =O8/M8 -> 0.2 | Q8: Low Profit
A9: O00008 | B9: 45895 | C9: =TEXT(B9,"MMMM") -> August | D9: C0157 | E9: P024 | F9: 1 | G9: Riya Sharma | H9: Ahmedabad | I9: Mouse | J9: =_xlfn.XLOOKUP(E9, Product_Master!$A$2:$A$101, Product_Master!$C$2:$C$101) -> Accessories | K9: =_xlfn.XLOOKUP(E9, Product_Master!$A$2:$A$101, Product_Master!$D$2:$D$101) -> 500 | L9: =_xlfn.XLOOKUP(E9, Product_Master!$A$2:$A$101, Product_Master!$E$2:$E$101) -> 800 | M9: =F9*L9 -> 800 | N9: =F9*K9 -> 500 | O9: =M9-N9 -> 300 | P9: =O9/M9 -> 0.375 | Q9: High Profit
A10: O00009 | B10: 45866 | C10: =TEXT(B10,"MMMM") -> July | D10: C0114 | E10: P027 | F10: 4 | G10: Riya Sharma | H10: Jaipur | I10: Laptop | J10: =_xlfn.XLOOKUP(E10, Product_Master!$A$2:$A$101, Product_Master!$C$2:$C$101) -> Electronics | K10: =_xlfn.XLOOKUP(E10, Product_Master!$A$2:$A$101, Product_Master!$D$2:$D$101) -> 42000 | L10: =_xlfn.XLOOKUP(E10, Product_Master!$A$2:$A$101, Product_Master!$E$2:$E$101) -> 50000 | M10: =F10*L10 -> 200000 | N10: =F10*K10 -> 168000 | O10: =M10-N10 -> 32000 | P10: =O10/M10 -> 0.16 | Q10: Low Profit
A11: O00010 | B11: 45853 | C11: =TEXT(B11,"MMMM") -> July | D11: C0218 | E11: P035 | F11: 5 | G11: Priya Verma | H11: Noida | I11: Monitor | J11: =_xlfn.XLOOKUP(E11, Product_Master!$A$2:$A$101, Product_Master!$C$2:$C$101) -> Accessories | K11: =_xlfn.XLOOKUP(E11, Product_Master!$A$2:$A$101, Product_Master!$D$2:$D$101) -> 9000 | L11: =_xlfn.XLOOKUP(E11, Product_Master!$A$2:$A$101, Product_Master!$E$2:$E$101) -> 12000 | M11: =F11*L11 -> 60000 | N11: =F11*K11 -> 45000 | O11: =M11-N11 -> 15000 | P11: =O11/M11 -> 0.25 | Q11: High Profit
A12: O00011 | B12: 45758 | C12: =TEXT(B12,"MMMM") -> April | D12: C0063 | E12: P032 | F12: 4 | G12: Vikas Yadav | H12: Lucknow | I12: Mobile | J12: =_xlfn.XLOOKUP(E12, Product_Master!$A$2:$A$101, Product_Master!$C$2:$C$101) -> Electronics | K12: =_xlfn.XLOOKUP(E12, Product_Master!$A$2:$A$101, Product_Master!$D$2:$D$101) -> 20000 | L12: =_xlfn.XLOOKUP(E12, Product_Master!$A$2:$A$101, Product_Master!$E$2:$E$101) -> 25000 | M12: =F12*L12 -> 100000 | N12: =F12*K12 -> 80000 | O12: =M12-N12 -> 20000 | P12: =O12/M12 -> 0.2 | Q12: Low Profit
A13: O00012 | B13: 45667 | C13: =TEXT(B13,"MMMM") -> January | D13: C9999 | E13: P075 | F13: 1 | G13: Invailid | I13: Mobile | J13: =_xlfn.XLOOKUP(E13, Product_Master!$A$2:$A$101, Product_Master!$C$2:$C$101) -> Electronics | K13: =_xlfn.XLOOKUP(E13, Product_Master!$A$2:$A$101, Product_Master!$D$2:$D$101) -> 20000 | L13: =_xlfn.XLOOKUP(E13, Product_Master!$A$2:$A$101, Product_Master!$E$2:$E$101) -> 25000 | M13: =F13*L13 -> 25000 | N13: =F13*K13 -> 20000 | O13: =M13-N13 -> 5000 | P13: =O13/M13 -> 0.2 | Q13: Low Profit
A14: O00013 | B14: 45937 | C14: =TEXT(B14,"MMMM") -> October | D14: C0162 | E14: P005 | F14: 2 | G14: Riya Sharma | H14: Noida | I14: Mouse | J14: =_xlfn.XLOOKUP(E14, Product_Master!$A$2:$A$101, Product_Master!$C$2:$C$101) -> Accessories | K14: =_xlfn.XLOOKUP(E14, Product_Master!$A$2:$A$101, Product_Master!$D$2:$D$101) -> 500 | L14: =_xlfn.XLOOKUP(E14, Product_Master!$A$2:$A$101, Product_Master!$E$2:$E$101) -> 800 | M14: =F14*L14 -> 1600 | N14: =F14*K14 -> 1000 | O14: =M14-N14 -> 600 | P14: =O14/M14 -> 0.375 | Q14: High Profit
A15: O00014 | B15: 46003 | C15: =TEXT(B15,"MMMM") -> December | D15: C0172 | E15: P014 | F15: 1 | G15: Priya Verma | H15: Delhi | I15: Mouse | J15: =_xlfn.XLOOKUP(E15, Product_Master!$A$2:$A$101, Product_Master!$C$2:$C$101) -> Accessories | K15: =_xlfn.XLOOKUP(E15, Product_Master!$A$2:$A$101, Product_Master!$D$2:$D$101) -> 500 | L15: =_xlfn.XLOOKUP(E15, Product_Master!$A$2:$A$101, Product_Master!$E$2:$E$101) -> 800 | M15: =F15*L15 -> 800 | N15: =F15*K15 -> 500 | O15: =M15-N15 -> 300 | P15: =O15/M15 -> 0.375 | Q15: High Profit
A16: O00015 | B16: 45962 | C16: =TEXT(B16,"MMMM") -> November | D16: C0077 | E16: P043 | F16: 3 | G16: Karan Patel | H16: Noida | I16: Printer | J16: =_xlfn.XLOOKUP(E16, Product_Master!$A$2:$A$101, Product_Master!$C$2:$C$101) -> Electronics | K16: =_xlfn.XLOOKUP(E16, Product_Master!$A$2:$A$101, Product_Master!$D$2:$D$101) -> 12000 | L16: =_xlfn.XLOOKUP(E16, Product_Master!$A$2:$A$101, Product_Master!$E$2:$E$101) -> 15000 | M16: =F16*L16 -> 45000 | N16: =F16*K16 -> 36000 | O16: =M16-N16 -> 9000 | P16: =O16/M16 -> 0.2 | Q16: Low Profit
A17: O00016 | B17: 45767 | C17: =TEXT(B17,"MMMM") -> April | D17: C0164 | E17: P091 | F17: 1 | G17: Arjun Mehta | H17: Pune | I17: Monitor | J17: =_xlfn.XLOOKUP(E17, Product_Master!$A$2:$A$101, Product_Master!$C$2:$C$101) -> Accessories | K17: =_xlfn.XLOOKUP(E17, Product_Master!$A$2:$A$101, Product_Master!$D$2:$D$101) -> 9000 | L17: =_xlfn.XLOOKUP(E17, Product_Master!$A$2:$A$101, Product_Master!$E$2:$E$101) -> 12000 | M17: =F17*L17 -> 12000 | N17: =F17*K17 -> 9000 | O17: =M17-N17 -> 3000 | P17: =O17/M17 -> 0.25 | Q17: High Profit
A18: O00017 | B18: 45971 | C18: =TEXT(B18,"MMMM") -> November | D18: C0259 | E18: P085 | F18: 3 | G18: Priya Verma | H18: Jaipur | I18: Keyboard | J18: =_xlfn.XLOOKUP(E18, Product_Master!$A$2:$A$101, Product_Master!$C$2:$C$101) -> Accessories | K18: =_xlfn.XLOOKUP(E18, Product_Master!$A$2:$A$101, Product_Master!$D$2:$D$101) -> 900 | L18: =_xlfn.XLOOKUP(E18, Product_Master!$A$2:$A$101, Product_Master!$E$2:$E$101) -> 1500 | M18: =F18*L18 -> 4500 | N18: =F18*K18 -> 2700 | O18: =M18-N18 -> 1800 | P18: =O18/M18 -> 0.4 | Q18: High Profit
A19: O00018 | B19: 45895 | C19: =TEXT(B19,"MMMM") -> August | D19: C0287 | E19: P100 | F19: 3 | G19: Riya Sharma | H19: Noida | I19: Speaker | J19: =_xlfn.XLOOKUP(E19, Product_Master!$A$2:$A$101, Product_Master!$C$2:$C$101) -> Accessories | K19: =_xlfn.XLOOKUP(E19, Product_Master!$A$2:$A$101, Product_Master!$D$2:$D$101) -> 2000 | L19: =_xlfn.XLOOKUP(E19, Product_Master!$A$2:$A$101, Product_Master!$E$2:$E$101) -> 3000 | M19: =F19*L19 -> 9000 | N19: =F19*K19 -> 6000 | O19: =M19-N19 -> 3000 | P19: =O19/M19 -> 0.33333333 | Q19: High Profit
A20: O00019 | B20: 45857 | C20: =TEXT(B20,"MMMM") -> July | D20: C0077 | E20: P044 | F20: 3 | G20: Karan Patel | H20: Noida | I20: Laptop | J20: =_xlfn.XLOOKUP(E20, Product_Master!$A$2:$A$101, Product_Master!$C$2:$C$101) -> Electronics | K20: =_xlfn.XLOOKUP(E20, Product_Master!$A$2:$A$101, Product_Master!$D$2:$D$101) -> 42000 | L20: =_xlfn.XLOOKUP(E20, Product_Master!$A$2:$A$101, Product_Master!$E$2:$E$101) -> 50000 | M20: =F20*L20 -> 150000 | N20: =F20*K20 -> 126000 | O20: =M20-N20 -> 24000 | P20: =O20/M20 -> 0.16 | Q20: Low Profit
A21: O00020 | B21: 45693 | C21: =TEXT(B21,"MMMM") -> February | D21: C0219 | E21: P010 | F21: 3 | G21: Riya Sharma | H21: Lucknow | I21: Monitor | J21: =_xlfn.XLOOKUP(E21, Product_Master!$A$2:$A$101, Product_Master!$C$2:$C$101) -> Accessories | K21: =_xlfn.XLOOKUP(E21, Product_Master!$A$2:$A$101, Product_Master!$D$2:$D$101) -> 9000 | L21: =_xlfn.XLOOKUP(E21, Product_Master!$A$2:$A$101, Product_Master!$E$2:$E$101) -> 12000 | M21: =F21*L21 -> 36000 | N21: =F21*K21 -> 27000 | O21: =M21-N21 -> 9000 | P21: =O21/M21 -> 0.25 | Q21: High Profit
A22: O00021 | B22: 45969 | C22: =TEXT(B22,"MMMM") -> November | D22: C8888 | E22: P001 | F22: 5 | G22: Invailid | I22: Mobile | J22: =_xlfn.XLOOKUP(E22, Product_Master!$A$2:$A$101, Product_Master!$C$2:$C$101) -> Electronics | K22: =_xlfn.XLOOKUP(E22, Product_Master!$A$2:$A$101, Product_Master!$D$2:$D$101) -> 20000 | L22: =_xlfn.XLOOKUP(E22, Product_Master!$A$2:$A$101, Product_Master!$E$2:$E$101) -> 25000 | M22: =F22*L22 -> 125000 | N22: =F22*K22 -> 100000 | O22: =M22-N22 -> 25000 | P22: =O22/M22 -> 0.2 | Q22: Low Profit
A23: O00022 | B23: 45809 | C23: =TEXT(B23,"MMMM") -> June | D23: C0197 | E23: P024 | F23: 5 | G23: Arjun Mehta | H23: Jaipur | I23: Mouse | J23: =_xlfn.XLOOKUP(E23, Product_Master!$A$2:$A$101, Product_Master!$C$2:$C$101) -> Accessories | K23: =_xlfn.XLOOKUP(E23, Product_Master!$A$2:$A$101, Product_Master!$D$2:$D$101) -> 500 | L23: =_xlfn.XLOOKUP(E23, Product_Master!$A$2:$A$101, Product_Master!$E$2:$E$101) -> 800 | M23: =F23*L23 -> 4000 | N23: =F23*K23 -> 2500 | O23: =M23-N23 -> 1500 | P23: =O23/M23 -> 0.375 | Q23: High Profit
A24: O00023 | B24: 45803 | C24: =TEXT(B24,"MMMM") -> May | D24: C0263 | E24: P081 | F24: 3 | G24: Neha Singh | I24: Tablet | J24: =_xlfn.XLOOKUP(E24, Product_Master!$A$2:$A$101, Product_Master!$C$2:$C$101) -> Electronics | K24: =_xlfn.XLOOKUP(E24, Product_Master!$A$2:$A$101, Product_Master!$D$2:$D$101) -> 15000 | L24: =_xlfn.XLOOKUP(E24, Product_Master!$A$2:$A$101, Product_Master!$E$2:$E$101) -> 18000 | M24: =F24*L24 -> 54000 | N24: =F24*K24 -> 45000 | O24: =M24-N24 -> 9000 | P24: =O24/M24 -> 0.16666667 | Q24: Low Profit
A25: O00024 | B25: 45739 | C25: =TEXT(B25,"MMMM") -> March | D25: C0217 | E25: P026 | F25: 1 | G25: Anjali Gupta | H25: Noida | I25: Monitor | J25: =_xlfn.XLOOKUP(E25, Product_Master!$A$2:$A$101, Product_Master!$C$2:$C$101) -> Accessories | K25: =_xlfn.XLOOKUP(E25, Product_Master!$A$2:$A$101, Product_Master!$D$2:$D$101) -> 9000 | L25: =_xlfn.XLOOKUP(E25, Product_Master!$A$2:$A$101, Product_Master!$E$2:$E$101) -> 12000 | M25: =F25*L25 -> 12000 | N25: =F25*K25 -> 9000 | O25: =M25-N25 -> 3000 | P25: =O25/M25 -> 0.25 | Q25: High Profit
A26: O00025 | B26: 45658 | C26: =TEXT(B26,"MMMM") -> January | D26: C0168 | E26: P048 | F26: 3 | G26: Vikas Yadav | H26: Lucknow | I26: Tablet | J26: =_xlfn.XLOOKUP(E26, Product_Master!$A$2:$A$101, Product_Master!$C$2:$C$101) -> Electronics | K26: =_xlfn.XLOOKUP(E26, Product_Master!$A$2:$A$101, Product_Master!$D$2:$D$101) -> 15000 | L26: =_xlfn.XLOOKUP(E26, Product_Master!$A$2:$A$101, Product_Master!$E$2:$E$101) -> 18000 | M26: =F26*L26 -> 54000 | N26: =F26*K26 -> 45000 | O26: =M26-N26 -> 9000 | P26: =O26/M26 -> 0.16666667 | Q26: Low Profit
A27: O00026 | B27: 45738 | C27: =TEXT(B27,"MMMM") -> March | D27: C0244 | E27: P023 | F27: 5 | G27: Amit Kumar | H27: Mumbai | I27: Speaker | J27: =_xlfn.XLOOKUP(E27, Product_Master!$A$2:$A$101, Product_Master!$C$2:$C$101) -> Accessories | K27: =_xlfn.XLOOKUP(E27, Product_Master!$A$2:$A$101, Product_Master!$D$2:$D$101) -> 2000 | L27: =_xlfn.XLOOKUP(E27, Product_Master!$A$2:$A$101, Product_Master!$E$2:$E$101) -> 3000 | M27: =F27*L27 -> 15000 | N27: =F27*K27 -> 10000 | O27: =M27-N27 -> 5000 | P27: =O27/M27 -> 0.33333333 | Q27: High Profit
A28: O00027 | B28: 45665 | C28: =TEXT(B28,"MMMM") -> January | D28: C0119 | E28: P082 | F28: 1 | G28: Anjali Gupta | H28: Chandigarh | I28: Tablet | J28: =_xlfn.XLOOKUP(E28, Product_Master!$A$2:$A$101, Product_Master!$C$2:$C$101) -> Electronics | K28: =_xlfn.XLOOKUP(E28, Product_Master!$A$2:$A$101, Product_Master!$D$2:$D$101) -> 15000 | L28: =_xlfn.XLOOKUP(E28, Product_Master!$A$2:$A$101, Product_Master!$E$2:$E$101) -> 18000 | M28: =F28*L28 -> 18000 | N28: =F28*K28 -> 15000 | O28: =M28-N28 -> 3000 | P28: =O28/M28 -> 0.16666667 | Q28: Low Profit
A29: O00028 | B29: 45867 | C29: =TEXT(B29,"MMMM") -> July | D29: C0058 | E29: P099 | F29: 4 | G29: Sneha Roy | H29: Ahmedabad | I29: Keyboard | J29: =_xlfn.XLOOKUP(E29, Product_Master!$A$2:$A$101, Product_Master!$C$2:$C$101) -> Accessories | K29: =_xlfn.XLOOKUP(E29, Product_Master!$A$2:$A$101, Product_Master!$D$2:$D$101) -> 900 | L29: =_xlfn.XLOOKUP(E29, Product_Master!$A$2:$A$101, Product_Master!$E$2:$E$101) -> 1500 | M29: =F29*L29 -> 6000 | N29: =F29*K29 -> 3600 | O29: =M29-N29 -> 2400 | P29: =O29/M29 -> 0.4 | Q29: High Profit
A30: O00029 | B30: 45834 | C30: =TEXT(B30,"MMMM") -> June | D30: C0055 | E30: P040 | F30: 1 | G30: Sneha Roy | H30: Chandigarh | I30: Laptop | J30: =_xlfn.XLOOKUP(E30, Product_Master!$A$2:$A$101, Product_Master!$C$2:$C$101) -> Electronics | K30: =_xlfn.XLOOKUP(E30, Product_Master!$A$2:$A$101, Product_Master!$D$2:$D$101) -> 42000 | L30: =_xlfn.XLOOKUP(E30, Product_Master!$A$2:$A$101, Product_Master!$E$2:$E$101) -> 50000 | M30: =F30*L30 -> 50000 | N30: =F30*K30 -> 42000 | O30: =M30-N30 -> 8000 | P30: =O30/M30 -> 0.16 | Q30: Low Profit
A31: O00030 | B31: 45877 | C31: =TEXT(B31,"MMMM") -> August | D31: C0024 | E31: P086 | F31: 3 | G31: Karan Patel | H31: Ahmedabad | I31: Laptop | J31: =_xlfn.XLOOKUP(E31, Product_Master!$A$2:$A$101, Product_Master!$C$2:$C$101) -> Electronics | K31: =_xlfn.XLOOKUP(E31, Product_Master!$A$2:$A$101, Product_Master!$D$2:$D$101) -> 42000 | L31: =_xlfn.XLOOKUP(E31, Product_Master!$A$2:$A$101, Product_Master!$E$2:$E$101) -> 50000 | M31: =F31*L31 -> 150000 | N31: =F31*K31 -> 126000 | O31: =M31-N31 -> 24000 | P31: =O31/M31 -> 0.16 | Q31: Low Profit
A32: O00031 | B32: 45751 | C32: =TEXT(B32,"MMMM") -> April | D32: C0014 | E32: P044 | F32: 4 | G32: Riya Sharma | H32: Jaipur | I32: Laptop | J32: =_xlfn.XLOOKUP(E32, Product_Master!$A$2:$A$101, Product_Master!$C$2:$C$101) -> Electronics | K32: =_xlfn.XLOOKUP(E32, Product_Master!$A$2:$A$101, Product_Master!$D$2:$D$101) -> 42000 | L32: =_xlfn.XLOOKUP(E32, Product_Master!$A$2:$A$101, Product_Master!$E$2:$E$101) -> 50000 | M32: =F32*L32 -> 200000 | N32: =F32*K32 -> 168000 | O32: =M32-N32 -> 32000 | P32: =O32/M32 -> 0.16 | Q32: Low Profit
A33: O00032 | B33: 45724 | C33: =TEXT(B33,"MMMM") -> March | D33: C0103 | E33: P060 | F33: 5 | G33: Mohan Das | H33: Mumbai | I33: Mouse | J33: =_xlfn.XLOOKUP(E33, Product_Master!$A$2:$A$101, Product_Master!$C$2:$C$101) -> Accessories | K33: =_xlfn.XLOOKUP(E33, Product_Master!$A$2:$A$101, Product_Master!$D$2:$D$101) -> 500 | L33: =_xlfn.XLOOKUP(E33, Product_Master!$A$2:$A$101, Product_Master!$E$2:$E$101) -> 800 | M33: =F33*L33 -> 4000 | N33: =F33*K33 -> 2500 | O33: =M33-N33 -> 1500 | P33: =O33/M33 -> 0.375 | Q33: High Profit
A34: O00033 | B34: 45847 | C34: =TEXT(B34,"MMMM") -> July | D34: C0294 | E34: P088 | F34: 3 | G34: Mohan Das | H34: Chandigarh | I34: Mouse | J34: =_xlfn.XLOOKUP(E34, Product_Master!$A$2:$A$101, Product_Master!$C$2:$C$101) -> Accessories | K34: =_xlfn.XLOOKUP(E34, Product_Master!$A$2:$A$101, Product_Master!$D$2:$D$101) -> 500 | L34: =_xlfn.XLOOKUP(E34, Product_Master!$A$2:$A$101, Product_Master!$E$2:$E$101) -> 800 | M34: =F34*L34 -> 2400 | N34: =F34*K34 -> 1500 | O34: =M34-N34 -> 900 | P34: =O34/M34 -> 0.375 | Q34: High Profit
A35: O00034 | B35: 45765 | C35: =TEXT(B35,"MMMM") -> April | D35: C0182 | E35: P016 | F35: 4 | G35: Amit Kumar | H35: Ahmedabad | I35: Mobile | J35: =_xlfn.XLOOKUP(E35, Product_Master!$A$2:$A$101, Product_Master!$C$2:$C$101) -> Electronics | K35: =_xlfn.XLOOKUP(E35, Product_Master!$A$2:$A$101, Product_Master!$D$2:$D$101) -> 20000 | L35: =_xlfn.XLOOKUP(E35, Product_Master!$A$2:$A$101, Product_Master!$E$2:$E$101) -> 25000 | M35: =F35*L35 -> 100000 | N35: =F35*K35 -> 80000 | O35: =M35-N35 -> 20000 | P35: =O35/M35 -> 0.2 | Q35: Low Profit
A36: O00035 | B36: 45918 | C36: =TEXT(B36,"MMMM") -> September | D36: C0280 | E36: P075 | F36: 2 | G36: Amit Kumar | H36: Pune | I36: Mobile | J36: =_xlfn.XLOOKUP(E36, Product_Master!$A$2:$A$101, Product_Master!$C$2:$C$101) -> Electronics | K36: =_xlfn.XLOOKUP(E36, Product_Master!$A$2:$A$101, Product_Master!$D$2:$D$101) -> 20000 | L36: =_xlfn.XLOOKUP(E36, Product_Master!$A$2:$A$101, Product_Master!$E$2:$E$101) -> 25000 | M36: =F36*L36 -> 50000 | N36: =F36*K36 -> 40000 | O36: =M36-N36 -> 10000 | P36: =O36/M36 -> 0.2 | Q36: Low Profit
... A66: O00065 | B66: 45854 | C66: =TEXT(B66,"MMMM") -> July | D66: C0248 | E66: P057 | F66: 5 | G66: Amit Kumar | H66: Delhi | I66: Laptop | J66: =_xlfn.XLOOKUP(E66, Product_Master!$A$2:$A$101, Product_Master!$C$2:$C$101) -> Electronics | K66: =_xlfn.XLOOKUP(E66, Product_Master!$A$2:$A$101, Product_Master!$D$2:$D$101) -> 42000 | L66: =_xlfn.XLOOKUP(E66, Product_Master!$A$2:$A$101, Product_Master!$E$2:$E$101) -> 50000 | M66: =F66*L66 -> 250000 | N66: =F66*K66 -> 210000 | O66: =M66-N66 -> 40000 | P66: =O66/M66 -> 0.16 | Q66: Low Profit
A67: O00066 | B67: 45799 | C67: =TEXT(B67,"MMMM") -> May | D67: C8888 | E67: P057 | F67: 1 | G67: Invailid | I67: Laptop | J67: =_xlfn.XLOOKUP(E67, Product_Master!$A$2:$A$101, Product_Master!$C$2:$C$101) -> Electronics | K67: =_xlfn.XLOOKUP(E67, Product_Master!$A$2:$A$101, Product_Master!$D$2:$D$101) -> 42000 | L67: =_xlfn.XLOOKUP(E67, Product_Master!$A$2:$A$101, Product_Master!$E$2:$E$101) -> 50000 | M67: =F67*L67 -> 50000 | N67: =F67*K67 -> 42000 | O67: =M67-N67 -> 8000 | P67: =O67/M67 -> 0.16 | Q67: Low Profit
A68: O00067 | B68: 45971 | C68: =TEXT(B68,"MMMM") -> November | D68: C0075 | E68: P090 | F68: 2 | G68: Mohan Das | H68: Jaipur | I68: Printer | J68: =_xlfn.XLOOKUP(E68, Product_Master!$A$2:$A$101, Product_Master!$C$2:$C$101) -> Electronics | K68: =_xlfn.XLOOKUP(E68, Product_Master!$A$2:$A$101, Product_Master!$D$2:$D$101) -> 12000 | L68: =_xlfn.XLOOKUP(E68, Product_Master!$A$2:$A$101, Product_Master!$E$2:$E$101) -> 15000 | M68: =F68*L68 -> 30000 | N68: =F68*K68 -> 24000 | O68: =M68-N68 -> 6000 | P68: =O68/M68 -> 0.2 | Q68: Low Profit
A69: O00068 | B69: 45688 | C69: =TEXT(B69,"MMMM") -> January | D69: C0108 | E69: P002 | F69: 1 | G69: Priya Verma | H69: Lucknow | I69: Mouse | J69: =_xlfn.XLOOKUP(E69, Product_Master!$A$2:$A$101, Product_Master!$C$2:$C$101) -> Accessories | K69: =_xlfn.XLOOKUP(E69, Product_Master!$A$2:$A$101, Product_Master!$D$2:$D$101) -> 500 | L69: =_xlfn.XLOOKUP(E69, Product_Master!$A$2:$A$101, Product_Master!$E$2:$E$101) -> 800 | M69: =F69*L69 -> 800 | N69: =F69*K69 -> 500 | O69: =M69-N69 -> 300 | P69: =O69/M69 -> 0.375 | Q69: High Profit
...

Sheet Analysis
E4: KPI | F4: Value
E6: Total Revenue | F6: =SUM(Clean_Data!M2:M1001) -> 47763300
E7: Total Profit | F7: =SUM(Clean_Data!O2:O1001) -> 9157700
E8: Profit Margin % | F8: =F7/F6 -> 0.19173089
E9: Total Orders | F9: =COUNTA(Clean_Data!A2:A1001) -> 1000
E10: Total Quantity Sold | F10: =SUM(Clean_Data!F2:F1001) -> 3031
E11: Avarage Order Value | F11: =AVERAGE(Clean_Data!M2:M1001) -> 47763.3
E12: Highest Order | F12: =MAX(Clean_Data!M2:M1001) -> 250000
E13: Lowest Order | F13: =MIN(Clean_Data!M3:M1002) -> 800
E14: Top Product | F14: =_xlfn.XLOOKUP(LARGE(Clean_Data!M2:M1001,1 ),Clean_Data!M2:M1001,Clean_Data!I2:I1001) -> Laptop
E15: Top Customer | F15: Riya sharma
E16: Top City | F16: Jaipur

Sheet Dashboard
A1: Build Dashboard Here
B3: Retail Store Sales Dashboard
U6: Business Insights
U9: ✔ Laptop generated highest revenue.
U11: ✔ Riya Sharma achieved highest sales.
U13: ✔ Jaipur is the top performing city.
U15: ✔ Electronics contributes 78% of total revenue.
U17: ✔ Revenue and Profit are highest in Jan ,mar , Des .
